ExponentialRetryRequestExecuter Error: 0 : 15:52:58.0317471 : 1-nunit3-console.exe : Error while invoking '<Start>b__4' method. Current attempt: 0. Waiting 8 seconds and retrying it.
System.Net.Http.HttpRequestException: An error occurred while sending the request. ---> System.Net.WebException: Unable to connect to the remote server ---> System.Net.Sockets.SocketException: No connection could be made because the target machine actively refused it 127.0.0.1:80
   at System.Net.Sockets.Socket.InternalEndConnect(IAsyncResult asyncResult)
   at System.Net.Sockets.Socket.EndConnect(IAsyncResult asyncResult)
   at System.Net.ServicePoint.ConnectSocketInternal(Boolean connectFailure, Socket s4, Socket s6, Socket& socket, IPAddress& address, ConnectSocketState state, IAsyncResult asyncResult, Exception& exception)
   --- End of inner exception stack trace ---
   at System.Net.HttpWebRequest.EndGetRequestStream(IAsyncResult asyncResult, TransportContext& context)
   at System.Net.Http.HttpClientHandler.GetRequestStreamCallback(IAsyncResult ar)
   --- End of inner exception stack trace ---
   at System.Runtime.ExceptionServices.ExceptionDispatchInfo.Throw()
   at System.Runtime.CompilerServices.TaskAwaiter.HandleNonSuccessAndDebuggerNotification(Task task)
   at ReportPortal.Client.Resources.ServiceBaseResource.<SendHttpRequestAsync>d__12`1.MoveNext()
--- End of stack trace from previous location where exception was thrown ---
   at System.Runtime.ExceptionServices.ExceptionDispatchInfo.Throw()
   at System.Runtime.CompilerServices.TaskAwaiter.HandleNonSuccessAndDebuggerNotification(Task task)
   at ReportPortal.Shared.Internal.Delegating.BaseRequestExecuter.<ExecuteAsync>d__0`1.MoveNext()
--- End of stack trace from previous location where exception was thrown ---
   at System.Runtime.ExceptionServices.ExceptionDispatchInfo.Throw()
   at ReportPortal.Shared.Internal.Delegating.ExponentialRetryRequestExecuter.<ExecuteAsync>d__14`1.MoveNext()
ExponentialRetryRequestExecuter Error: 0 : 15:53:29.1233276 : 1-nunit3-console.exe : Error while invoking '<Start>b__4' method. Current attempt: 1. Waiting 16 seconds and retrying it.
System.Net.Http.HttpRequestException: An error occurred while sending the request. ---> System.Net.WebException: Unable to connect to the remote server ---> System.Net.Sockets.SocketException: No connection could be made because the target machine actively refused it 127.0.0.1:80
   at System.Net.Sockets.Socket.InternalEndConnect(IAsyncResult asyncResult)
   at System.Net.Sockets.Socket.EndConnect(IAsyncResult asyncResult)
   at System.Net.ServicePoint.ConnectSocketInternal(Boolean connectFailure, Socket s4, Socket s6, Socket& socket, IPAddress& address, ConnectSocketState state, IAsyncResult asyncResult, Exception& exception)
   --- End of inner exception stack trace ---
   at System.Net.HttpWebRequest.EndGetRequestStream(IAsyncResult asyncResult, TransportContext& context)
   at System.Net.Http.HttpClientHandler.GetRequestStreamCallback(IAsyncResult ar)
   --- End of inner exception stack trace ---
   at System.Runtime.ExceptionServices.ExceptionDispatchInfo.Throw()
   at System.Runtime.CompilerServices.TaskAwaiter.HandleNonSuccessAndDebuggerNotification(Task task)
   at ReportPortal.Client.Resources.ServiceBaseResource.<SendHttpRequestAsync>d__12`1.MoveNext()
--- End of stack trace from previous location where exception was thrown ---
   at System.Runtime.ExceptionServices.ExceptionDispatchInfo.Throw()
   at System.Runtime.CompilerServices.TaskAwaiter.HandleNonSuccessAndDebuggerNotification(Task task)
   at ReportPortal.Shared.Internal.Delegating.BaseRequestExecuter.<ExecuteAsync>d__0`1.MoveNext()
--- End of stack trace from previous location where exception was thrown ---
   at System.Runtime.ExceptionServices.ExceptionDispatchInfo.Throw()
   at ReportPortal.Shared.Internal.Delegating.ExponentialRetryRequestExecuter.<ExecuteAsync>d__14`1.MoveNext()
ExponentialRetryRequestExecuter Error: 0 : 15:54:08.2153183 : 1-nunit3-console.exe : Error while invoking '<Start>b__4' method. Current attempt: 2.
System.Net.Http.HttpRequestException: An error occurred while sending the request. ---> System.Net.WebException: Unable to connect to the remote server ---> System.Net.Sockets.SocketException: No connection could be made because the target machine actively refused it 127.0.0.1:80
   at System.Net.Sockets.Socket.InternalEndConnect(IAsyncResult asyncResult)
   at System.Net.Sockets.Socket.EndConnect(IAsyncResult asyncResult)
   at System.Net.ServicePoint.ConnectSocketInternal(Boolean connectFailure, Socket s4, Socket s6, Socket& socket, IPAddress& address, ConnectSocketState state, IAsyncResult asyncResult, Exception& exception)
   --- End of inner exception stack trace ---
   at System.Net.HttpWebRequest.EndGetRequestStream(IAsyncResult asyncResult, TransportContext& context)
   at System.Net.Http.HttpClientHandler.GetRequestStreamCallback(IAsyncResult ar)
   --- End of inner exception stack trace ---
   at System.Runtime.ExceptionServices.ExceptionDispatchInfo.Throw()
   at System.Runtime.CompilerServices.TaskAwaiter.HandleNonSuccessAndDebuggerNotification(Task task)
   at ReportPortal.Client.Resources.ServiceBaseResource.<SendHttpRequestAsync>d__12`1.MoveNext()
--- End of stack trace from previous location where exception was thrown ---
   at System.Runtime.ExceptionServices.ExceptionDispatchInfo.Throw()
   at System.Runtime.CompilerServices.TaskAwaiter.HandleNonSuccessAndDebuggerNotification(Task task)
   at ReportPortal.Shared.Internal.Delegating.BaseRequestExecuter.<ExecuteAsync>d__0`1.MoveNext()
--- End of stack trace from previous location where exception was thrown ---
   at System.Runtime.ExceptionServices.ExceptionDispatchInfo.Throw()
   at ReportPortal.Shared.Internal.Delegating.ExponentialRetryRequestExecuter.<ExecuteAsync>d__14`1.MoveNext()
TestReporter Error: 0 : 15:54:08.2243100 : 1-nunit3-console.exe : System.Exception: Cannot start test item due parent failed to start. ---> System.AggregateException: One or more errors occurred. ---> System.Net.Http.HttpRequestException: An error occurred while sending the request. ---> System.Net.WebException: Unable to connect to the remote server ---> System.Net.Sockets.SocketException: No connection could be made because the target machine actively refused it 127.0.0.1:80
   at System.Net.Sockets.Socket.InternalEndConnect(IAsyncResult asyncResult)
   at System.Net.Sockets.Socket.EndConnect(IAsyncResult asyncResult)
   at System.Net.ServicePoint.ConnectSocketInternal(Boolean connectFailure, Socket s4, Socket s6, Socket& socket, IPAddress& address, ConnectSocketState state, IAsyncResult asyncResult, Exception& exception)
   --- End of inner exception stack trace ---
   at System.Net.HttpWebRequest.EndGetRequestStream(IAsyncResult asyncResult, TransportContext& context)
   at System.Net.Http.HttpClientHandler.GetRequestStreamCallback(IAsyncResult ar)
   --- End of inner exception stack trace ---
   at System.Runtime.ExceptionServices.ExceptionDispatchInfo.Throw()
   at System.Runtime.CompilerServices.TaskAwaiter.HandleNonSuccessAndDebuggerNotification(Task task)
   at ReportPortal.Client.Resources.ServiceBaseResource.<SendHttpRequestAsync>d__12`1.MoveNext()
--- End of stack trace from previous location where exception was thrown ---
   at System.Runtime.ExceptionServices.ExceptionDispatchInfo.Throw()
   at System.Runtime.CompilerServices.TaskAwaiter.HandleNonSuccessAndDebuggerNotification(Task task)
   at ReportPortal.Shared.Internal.Delegating.BaseRequestExecuter.<ExecuteAsync>d__0`1.MoveNext()
--- End of stack trace from previous location where exception was thrown ---
   at System.Runtime.ExceptionServices.ExceptionDispatchInfo.Throw()
   at ReportPortal.Shared.Internal.Delegating.ExponentialRetryRequestExecuter.<ExecuteAsync>d__14`1.MoveNext()
--- End of stack trace from previous location where exception was thrown ---
   at System.Runtime.ExceptionServices.ExceptionDispatchInfo.Throw()
   at ReportPortal.Shared.Internal.Delegating.ExponentialRetryRequestExecuter.<ExecuteAsync>d__14`1.MoveNext()
--- End of stack trace from previous location where exception was thrown ---
   at System.Runtime.ExceptionServices.ExceptionDispatchInfo.Throw()
   at System.Runtime.CompilerServices.TaskAwaiter.HandleNonSuccessAndDebuggerNotification(Task task)
   at ReportPortal.Shared.Reporter.LaunchReporter.<>c__DisplayClass25_0.<<Start>b__1>d.MoveNext()
--- End of stack trace from previous location where exception was thrown ---
   at System.Runtime.ExceptionServices.ExceptionDispatchInfo.Throw()
   at System.Runtime.CompilerServices.TaskAwaiter.HandleNonSuccessAndDebuggerNotification(Task task)
   at ReportPortal.Shared.Reporter.LaunchReporter.Sync()
   at ReportPortal.NUnitExtension.ReportPortalListener.FinishRun(String report) in C:\projects\agent-net-nunit\src\ReportPortal.NUnitExtension\ReportPortalListener.Launch.cs:line 113
   --- End of inner exception stack trace ---
   --- End of inner exception stack trace ---
TestReporter Error: 0 : 15:54:08.2303321 : 1-nunit3-console.exe : System.Exception: Cannot start test item due parent failed to start. ---> System.AggregateException: One or more errors occurred. ---> System.Exception: Cannot start test item due parent failed to start. ---> System.AggregateException: One or more errors occurred. ---> System.Net.Http.HttpRequestException: An error occurred while sending the request. ---> System.Net.WebException: Unable to connect to the remote server ---> System.Net.Sockets.SocketException: No connection could be made because the target machine actively refused it 127.0.0.1:80
   at System.Net.Sockets.Socket.InternalEndConnect(IAsyncResult asyncResult)
   at System.Net.Sockets.Socket.EndConnect(IAsyncResult asyncResult)
   at System.Net.ServicePoint.ConnectSocketInternal(Boolean connectFailure, Socket s4, Socket s6, Socket& socket, IPAddress& address, ConnectSocketState state, IAsyncResult asyncResult, Exception& exception)
   --- End of inner exception stack trace ---
   at System.Net.HttpWebRequest.EndGetRequestStream(IAsyncResult asyncResult, TransportContext& context)
   at System.Net.Http.HttpClientHandler.GetRequestStreamCallback(IAsyncResult ar)
   --- End of inner exception stack trace ---
   at System.Runtime.ExceptionServices.ExceptionDispatchInfo.Throw()
   at System.Runtime.CompilerServices.TaskAwaiter.HandleNonSuccessAndDebuggerNotification(Task task)
   at ReportPortal.Client.Resources.ServiceBaseResource.<SendHttpRequestAsync>d__12`1.MoveNext()
--- End of stack trace from previous location where exception was thrown ---
   at System.Runtime.ExceptionServices.ExceptionDispatchInfo.Throw()
   at System.Runtime.CompilerServices.TaskAwaiter.HandleNonSuccessAndDebuggerNotification(Task task)
   at ReportPortal.Shared.Internal.Delegating.BaseRequestExecuter.<ExecuteAsync>d__0`1.MoveNext()
--- End of stack trace from previous location where exception was thrown ---
   at System.Runtime.ExceptionServices.ExceptionDispatchInfo.Throw()
   at ReportPortal.Shared.Internal.Delegating.ExponentialRetryRequestExecuter.<ExecuteAsync>d__14`1.MoveNext()
--- End of stack trace from previous location where exception was thrown ---
   at System.Runtime.ExceptionServices.ExceptionDispatchInfo.Throw()
   at ReportPortal.Shared.Internal.Delegating.ExponentialRetryRequestExecuter.<ExecuteAsync>d__14`1.MoveNext()
--- End of stack trace from previous location where exception was thrown ---
   at System.Runtime.ExceptionServices.ExceptionDispatchInfo.Throw()
   at System.Runtime.CompilerServices.TaskAwaiter.HandleNonSuccessAndDebuggerNotification(Task task)
   at ReportPortal.Shared.Reporter.LaunchReporter.<>c__DisplayClass25_0.<<Start>b__1>d.MoveNext()
--- End of stack trace from previous location where exception was thrown ---
   at System.Runtime.ExceptionServices.ExceptionDispatchInfo.Throw()
   at System.Runtime.CompilerServices.TaskAwaiter.HandleNonSuccessAndDebuggerNotification(Task task)
   at ReportPortal.Shared.Reporter.LaunchReporter.Sync()
   at ReportPortal.NUnitExtension.ReportPortalListener.FinishRun(String report) in C:\projects\agent-net-nunit\src\ReportPortal.NUnitExtension\ReportPortalListener.Launch.cs:line 113
   --- End of inner exception stack trace ---
   --- End of inner exception stack trace ---
   at ReportPortal.Shared.Reporter.TestReporter.<>c__DisplayClass24_0.<<Start>b__0>d.MoveNext()
   --- End of inner exception stack trace ---
   --- End of inner exception stack trace ---
TestReporter Error: 0 : 15:54:08.2393089 : 1-nunit3-console.exe : System.Exception: Cannot start test item due parent failed to start. ---> System.AggregateException: One or more errors occurred. ---> System.Exception: Cannot start test item due parent failed to start. ---> System.AggregateException: One or more errors occurred. ---> System.Exception: Cannot start test item due parent failed to start. ---> System.AggregateException: One or more errors occurred. ---> System.Net.Http.HttpRequestException: An error occurred while sending the request. ---> System.Net.WebException: Unable to connect to the remote server ---> System.Net.Sockets.SocketException: No connection could be made because the target machine actively refused it 127.0.0.1:80
   at System.Net.Sockets.Socket.InternalEndConnect(IAsyncResult asyncResult)
   at System.Net.Sockets.Socket.EndConnect(IAsyncResult asyncResult)
   at System.Net.ServicePoint.ConnectSocketInternal(Boolean connectFailure, Socket s4, Socket s6, Socket& socket, IPAddress& address, ConnectSocketState state, IAsyncResult asyncResult, Exception& exception)
   --- End of inner exception stack trace ---
   at System.Net.HttpWebRequest.EndGetRequestStream(IAsyncResult asyncResult, TransportContext& context)
   at System.Net.Http.HttpClientHandler.GetRequestStreamCallback(IAsyncResult ar)
   --- End of inner exception stack trace ---
   at System.Runtime.ExceptionServices.ExceptionDispatchInfo.Throw()
   at System.Runtime.CompilerServices.TaskAwaiter.HandleNonSuccessAndDebuggerNotification(Task task)
   at ReportPortal.Client.Resources.ServiceBaseResource.<SendHttpRequestAsync>d__12`1.MoveNext()
--- End of stack trace from previous location where exception was thrown ---
   at System.Runtime.ExceptionServices.ExceptionDispatchInfo.Throw()
   at System.Runtime.CompilerServices.TaskAwaiter.HandleNonSuccessAndDebuggerNotification(Task task)
   at ReportPortal.Shared.Internal.Delegating.BaseRequestExecuter.<ExecuteAsync>d__0`1.MoveNext()
--- End of stack trace from previous location where exception was thrown ---
   at System.Runtime.ExceptionServices.ExceptionDispatchInfo.Throw()
   at ReportPortal.Shared.Internal.Delegating.ExponentialRetryRequestExecuter.<ExecuteAsync>d__14`1.MoveNext()
--- End of stack trace from previous location where exception was thrown ---
   at System.Runtime.ExceptionServices.ExceptionDispatchInfo.Throw()
   at ReportPortal.Shared.Internal.Delegating.ExponentialRetryRequestExecuter.<ExecuteAsync>d__14`1.MoveNext()
--- End of stack trace from previous location where exception was thrown ---
   at System.Runtime.ExceptionServices.ExceptionDispatchInfo.Throw()
   at System.Runtime.CompilerServices.TaskAwaiter.HandleNonSuccessAndDebuggerNotification(Task task)
   at ReportPortal.Shared.Reporter.LaunchReporter.<>c__DisplayClass25_0.<<Start>b__1>d.MoveNext()
--- End of stack trace from previous location where exception was thrown ---
   at System.Runtime.ExceptionServices.ExceptionDispatchInfo.Throw()
   at System.Runtime.CompilerServices.TaskAwaiter.HandleNonSuccessAndDebuggerNotification(Task task)
   at ReportPortal.Shared.Reporter.LaunchReporter.Sync()
   at ReportPortal.NUnitExtension.ReportPortalListener.FinishRun(String report) in C:\projects\agent-net-nunit\src\ReportPortal.NUnitExtension\ReportPortalListener.Launch.cs:line 113
   --- End of inner exception stack trace ---
   --- End of inner exception stack trace ---
   at ReportPortal.Shared.Reporter.TestReporter.<>c__DisplayClass24_0.<<Start>b__0>d.MoveNext()
   --- End of inner exception stack trace ---
   --- End of inner exception stack trace ---
   at ReportPortal.Shared.Reporter.TestReporter.<>c__DisplayClass24_0.<<Start>b__0>d.MoveNext()
   --- End of inner exception stack trace ---
   --- End of inner exception stack trace ---
TestReporter Error: 0 : 15:54:08.2483100 : 1-nunit3-console.exe : System.Exception: Cannot start test item due parent failed to start. ---> System.AggregateException: One or more errors occurred. ---> System.Exception: Cannot start test item due parent failed to start. ---> System.AggregateException: One or more errors occurred. ---> System.Exception: Cannot start test item due parent failed to start. ---> System.AggregateException: One or more errors occurred. ---> System.Exception: Cannot start test item due parent failed to start. ---> System.AggregateException: One or more errors occurred. ---> System.Net.Http.HttpRequestException: An error occurred while sending the request. ---> System.Net.WebException: Unable to connect to the remote server ---> System.Net.Sockets.SocketException: No connection could be made because the target machine actively refused it 127.0.0.1:80
   at System.Net.Sockets.Socket.InternalEndConnect(IAsyncResult asyncResult)
   at System.Net.Sockets.Socket.EndConnect(IAsyncResult asyncResult)
   at System.Net.ServicePoint.ConnectSocketInternal(Boolean connectFailure, Socket s4, Socket s6, Socket& socket, IPAddress& address, ConnectSocketState state, IAsyncResult asyncResult, Exception& exception)
   --- End of inner exception stack trace ---
   at System.Net.HttpWebRequest.EndGetRequestStream(IAsyncResult asyncResult, TransportContext& context)
   at System.Net.Http.HttpClientHandler.GetRequestStreamCallback(IAsyncResult ar)
   --- End of inner exception stack trace ---
   at System.Runtime.ExceptionServices.ExceptionDispatchInfo.Throw()
   at System.Runtime.CompilerServices.TaskAwaiter.HandleNonSuccessAndDebuggerNotification(Task task)
   at ReportPortal.Client.Resources.ServiceBaseResource.<SendHttpRequestAsync>d__12`1.MoveNext()
--- End of stack trace from previous location where exception was thrown ---
   at System.Runtime.ExceptionServices.ExceptionDispatchInfo.Throw()
   at System.Runtime.CompilerServices.TaskAwaiter.HandleNonSuccessAndDebuggerNotification(Task task)
   at ReportPortal.Shared.Internal.Delegating.BaseRequestExecuter.<ExecuteAsync>d__0`1.MoveNext()
--- End of stack trace from previous location where exception was thrown ---
   at System.Runtime.ExceptionServices.ExceptionDispatchInfo.Throw()
   at ReportPortal.Shared.Internal.Delegating.ExponentialRetryRequestExecuter.<ExecuteAsync>d__14`1.MoveNext()
--- End of stack trace from previous location where exception was thrown ---
   at System.Runtime.ExceptionServices.ExceptionDispatchInfo.Throw()
   at ReportPortal.Shared.Internal.Delegating.ExponentialRetryRequestExecuter.<ExecuteAsync>d__14`1.MoveNext()
--- End of stack trace from previous location where exception was thrown ---
   at System.Runtime.ExceptionServices.ExceptionDispatchInfo.Throw()
   at System.Runtime.CompilerServices.TaskAwaiter.HandleNonSuccessAndDebuggerNotification(Task task)
   at ReportPortal.Shared.Reporter.LaunchReporter.<>c__DisplayClass25_0.<<Start>b__1>d.MoveNext()
--- End of stack trace from previous location where exception was thrown ---
   at System.Runtime.ExceptionServices.ExceptionDispatchInfo.Throw()
   at System.Runtime.CompilerServices.TaskAwaiter.HandleNonSuccessAndDebuggerNotification(Task task)
   at ReportPortal.Shared.Reporter.LaunchReporter.Sync()
   at ReportPortal.NUnitExtension.ReportPortalListener.FinishRun(String report) in C:\projects\agent-net-nunit\src\ReportPortal.NUnitExtension\ReportPortalListener.Launch.cs:line 113
   --- End of inner exception stack trace ---
   --- End of inner exception stack trace ---
   at ReportPortal.Shared.Reporter.TestReporter.<>c__DisplayClass24_0.<<Start>b__0>d.MoveNext()
   --- End of inner exception stack trace ---
   --- End of inner exception stack trace ---
   at ReportPortal.Shared.Reporter.TestReporter.<>c__DisplayClass24_0.<<Start>b__0>d.MoveNext()
   --- End of inner exception stack trace ---
   --- End of inner exception stack trace ---
   at ReportPortal.Shared.Reporter.TestReporter.<>c__DisplayClass24_0.<<Start>b__0>d.MoveNext()
   --- End of inner exception stack trace ---
   --- End of inner exception stack trace ---
TestReporter Error: 0 : 15:54:08.2573100 : 1-nunit3-console.exe : System.Exception: Cannot start test item due parent failed to start. ---> System.AggregateException: One or more errors occurred. ---> System.Exception: Cannot start test item due parent failed to start. ---> System.AggregateException: One or more errors occurred. ---> System.Exception: Cannot start test item due parent failed to start. ---> System.AggregateException: One or more errors occurred. ---> System.Exception: Cannot start test item due parent failed to start. ---> System.AggregateException: One or more errors occurred. ---> System.Exception: Cannot start test item due parent failed to start. ---> System.AggregateException: One or more errors occurred. ---> System.Net.Http.HttpRequestException: An error occurred while sending the request. ---> System.Net.WebException: Unable to connect to the remote server ---> System.Net.Sockets.SocketException: No connection could be made because the target machine actively refused it 127.0.0.1:80
   at System.Net.Sockets.Socket.InternalEndConnect(IAsyncResult asyncResult)
   at System.Net.Sockets.Socket.EndConnect(IAsyncResult asyncResult)
   at System.Net.ServicePoint.ConnectSocketInternal(Boolean connectFailure, Socket s4, Socket s6, Socket& socket, IPAddress& address, ConnectSocketState state, IAsyncResult asyncResult, Exception& exception)
   --- End of inner exception stack trace ---
   at System.Net.HttpWebRequest.EndGetRequestStream(IAsyncResult asyncResult, TransportContext& context)
   at System.Net.Http.HttpClientHandler.GetRequestStreamCallback(IAsyncResult ar)
   --- End of inner exception stack trace ---
   at System.Runtime.ExceptionServices.ExceptionDispatchInfo.Throw()
   at System.Runtime.CompilerServices.TaskAwaiter.HandleNonSuccessAndDebuggerNotification(Task task)
   at ReportPortal.Client.Resources.ServiceBaseResource.<SendHttpRequestAsync>d__12`1.MoveNext()
--- End of stack trace from previous location where exception was thrown ---
   at System.Runtime.ExceptionServices.ExceptionDispatchInfo.Throw()
   at System.Runtime.CompilerServices.TaskAwaiter.HandleNonSuccessAndDebuggerNotification(Task task)
   at ReportPortal.Shared.Internal.Delegating.BaseRequestExecuter.<ExecuteAsync>d__0`1.MoveNext()
--- End of stack trace from previous location where exception was thrown ---
   at System.Runtime.ExceptionServices.ExceptionDispatchInfo.Throw()
   at ReportPortal.Shared.Internal.Delegating.ExponentialRetryRequestExecuter.<ExecuteAsync>d__14`1.MoveNext()
--- End of stack trace from previous location where exception was thrown ---
   at System.Runtime.ExceptionServices.ExceptionDispatchInfo.Throw()
   at ReportPortal.Shared.Internal.Delegating.ExponentialRetryRequestExecuter.<ExecuteAsync>d__14`1.MoveNext()
--- End of stack trace from previous location where exception was thrown ---
   at System.Runtime.ExceptionServices.ExceptionDispatchInfo.Throw()
   at System.Runtime.CompilerServices.TaskAwaiter.HandleNonSuccessAndDebuggerNotification(Task task)
   at ReportPortal.Shared.Reporter.LaunchReporter.<>c__DisplayClass25_0.<<Start>b__1>d.MoveNext()
--- End of stack trace from previous location where exception was thrown ---
   at System.Runtime.ExceptionServices.ExceptionDispatchInfo.Throw()
   at System.Runtime.CompilerServices.TaskAwaiter.HandleNonSuccessAndDebuggerNotification(Task task)
   at ReportPortal.Shared.Reporter.LaunchReporter.Sync()
   at ReportPortal.NUnitExtension.ReportPortalListener.FinishRun(String report) in C:\projects\agent-net-nunit\src\ReportPortal.NUnitExtension\ReportPortalListener.Launch.cs:line 113
   --- End of inner exception stack trace ---
   --- End of inner exception stack trace ---
   at ReportPortal.Shared.Reporter.TestReporter.<>c__DisplayClass24_0.<<Start>b__0>d.MoveNext()
   --- End of inner exception stack trace ---
   --- End of inner exception stack trace ---
   at ReportPortal.Shared.Reporter.TestReporter.<>c__DisplayClass24_0.<<Start>b__0>d.MoveNext()
   --- End of inner exception stack trace ---
   --- End of inner exception stack trace ---
   at ReportPortal.Shared.Reporter.TestReporter.<>c__DisplayClass24_0.<<Start>b__0>d.MoveNext()
   --- End of inner exception stack trace ---
   --- End of inner exception stack trace ---
   at ReportPortal.Shared.Reporter.TestReporter.<>c__DisplayClass24_0.<<Start>b__0>d.MoveNext()
   --- End of inner exception stack trace ---
   --- End of inner exception stack trace ---
TestReporter Error: 0 : 15:54:08.2573100 : 1-nunit3-console.exe : System.Exception: Cannot start test item due parent failed to start. ---> System.AggregateException: One or more errors occurred. ---> System.Exception: Cannot start test item due parent failed to start. ---> System.AggregateException: One or more errors occurred. ---> System.Exception: Cannot start test item due parent failed to start. ---> System.AggregateException: One or more errors occurred. ---> System.Exception: Cannot start test item due parent failed to start. ---> System.AggregateException: One or more errors occurred. ---> System.Exception: Cannot start test item due parent failed to start. ---> System.AggregateException: One or more errors occurred. ---> System.Net.Http.HttpRequestException: An error occurred while sending the request. ---> System.Net.WebException: Unable to connect to the remote server ---> System.Net.Sockets.SocketException: No connection could be made because the target machine actively refused it 127.0.0.1:80
   at System.Net.Sockets.Socket.InternalEndConnect(IAsyncResult asyncResult)
   at System.Net.Sockets.Socket.EndConnect(IAsyncResult asyncResult)
   at System.Net.ServicePoint.ConnectSocketInternal(Boolean connectFailure, Socket s4, Socket s6, Socket& socket, IPAddress& address, ConnectSocketState state, IAsyncResult asyncResult, Exception& exception)
   --- End of inner exception stack trace ---
   at System.Net.HttpWebRequest.EndGetRequestStream(IAsyncResult asyncResult, TransportContext& context)
   at System.Net.Http.HttpClientHandler.GetRequestStreamCallback(IAsyncResult ar)
   --- End of inner exception stack trace ---
   at System.Runtime.ExceptionServices.ExceptionDispatchInfo.Throw()
   at System.Runtime.CompilerServices.TaskAwaiter.HandleNonSuccessAndDebuggerNotification(Task task)
   at ReportPortal.Client.Resources.ServiceBaseResource.<SendHttpRequestAsync>d__12`1.MoveNext()
--- End of stack trace from previous location where exception was thrown ---
   at System.Runtime.ExceptionServices.ExceptionDispatchInfo.Throw()
   at System.Runtime.CompilerServices.TaskAwaiter.HandleNonSuccessAndDebuggerNotification(Task task)
   at ReportPortal.Shared.Internal.Delegating.BaseRequestExecuter.<ExecuteAsync>d__0`1.MoveNext()
--- End of stack trace from previous location where exception was thrown ---
   at System.Runtime.ExceptionServices.ExceptionDispatchInfo.Throw()
   at ReportPortal.Shared.Internal.Delegating.ExponentialRetryRequestExecuter.<ExecuteAsync>d__14`1.MoveNext()
--- End of stack trace from previous location where exception was thrown ---
   at System.Runtime.ExceptionServices.ExceptionDispatchInfo.Throw()
   at ReportPortal.Shared.Internal.Delegating.ExponentialRetryRequestExecuter.<ExecuteAsync>d__14`1.MoveNext()
--- End of stack trace from previous location where exception was thrown ---
   at System.Runtime.ExceptionServices.ExceptionDispatchInfo.Throw()
   at System.Runtime.CompilerServices.TaskAwaiter.HandleNonSuccessAndDebuggerNotification(Task task)
   at ReportPortal.Shared.Reporter.LaunchReporter.<>c__DisplayClass25_0.<<Start>b__1>d.MoveNext()
--- End of stack trace from previous location where exception was thrown ---
   at System.Runtime.ExceptionServices.ExceptionDispatchInfo.Throw()
   at System.Runtime.CompilerServices.TaskAwaiter.HandleNonSuccessAndDebuggerNotification(Task task)
   at ReportPortal.Shared.Reporter.LaunchReporter.Sync()
   at ReportPortal.NUnitExtension.ReportPortalListener.FinishRun(String report) in C:\projects\agent-net-nunit\src\ReportPortal.NUnitExtension\ReportPortalListener.Launch.cs:line 113
   --- End of inner exception stack trace ---
   --- End of inner exception stack trace ---
   at ReportPortal.Shared.Reporter.TestReporter.<>c__DisplayClass24_0.<<Start>b__0>d.MoveNext()
   --- End of inner exception stack trace ---
   --- End of inner exception stack trace ---
   at ReportPortal.Shared.Reporter.TestReporter.<>c__DisplayClass24_0.<<Start>b__0>d.MoveNext()
   --- End of inner exception stack trace ---
   --- End of inner exception stack trace ---
   at ReportPortal.Shared.Reporter.TestReporter.<>c__DisplayClass24_0.<<Start>b__0>d.MoveNext()
   --- End of inner exception stack trace ---
   --- End of inner exception stack trace ---
   at ReportPortal.Shared.Reporter.TestReporter.<>c__DisplayClass24_0.<<Start>b__0>d.MoveNext()
   --- End of inner exception stack trace ---
   --- End of inner exception stack trace ---
TestReporter Error: 0 : 15:54:08.2573100 : 1-nunit3-console.exe : System.Exception: Cannot start test item due parent failed to start. ---> System.AggregateException: One or more errors occurred. ---> System.Exception: Cannot start test item due parent failed to start. ---> System.AggregateException: One or more errors occurred. ---> System.Exception: Cannot start test item due parent failed to start. ---> System.AggregateException: One or more errors occurred. ---> System.Exception: Cannot start test item due parent failed to start. ---> System.AggregateException: One or more errors occurred. ---> System.Exception: Cannot start test item due parent failed to start. ---> System.AggregateException: One or more errors occurred. ---> System.Net.Http.HttpRequestException: An error occurred while sending the request. ---> System.Net.WebException: Unable to connect to the remote server ---> System.Net.Sockets.SocketException: No connection could be made because the target machine actively refused it 127.0.0.1:80
   at System.Net.Sockets.Socket.InternalEndConnect(IAsyncResult asyncResult)
   at System.Net.Sockets.Socket.EndConnect(IAsyncResult asyncResult)
   at System.Net.ServicePoint.ConnectSocketInternal(Boolean connectFailure, Socket s4, Socket s6, Socket& socket, IPAddress& address, ConnectSocketState state, IAsyncResult asyncResult, Exception& exception)
   --- End of inner exception stack trace ---
   at System.Net.HttpWebRequest.EndGetRequestStream(IAsyncResult asyncResult, TransportContext& context)
   at System.Net.Http.HttpClientHandler.GetRequestStreamCallback(IAsyncResult ar)
   --- End of inner exception stack trace ---
   at System.Runtime.ExceptionServices.ExceptionDispatchInfo.Throw()
   at System.Runtime.CompilerServices.TaskAwaiter.HandleNonSuccessAndDebuggerNotification(Task task)
   at ReportPortal.Client.Resources.ServiceBaseResource.<SendHttpRequestAsync>d__12`1.MoveNext()
--- End of stack trace from previous location where exception was thrown ---
   at System.Runtime.ExceptionServices.ExceptionDispatchInfo.Throw()
   at System.Runtime.CompilerServices.TaskAwaiter.HandleNonSuccessAndDebuggerNotification(Task task)
   at ReportPortal.Shared.Internal.Delegating.BaseRequestExecuter.<ExecuteAsync>d__0`1.MoveNext()
--- End of stack trace from previous location where exception was thrown ---
   at System.Runtime.ExceptionServices.ExceptionDispatchInfo.Throw()
   at ReportPortal.Shared.Internal.Delegating.ExponentialRetryRequestExecuter.<ExecuteAsync>d__14`1.MoveNext()
--- End of stack trace from previous location where exception was thrown ---
   at System.Runtime.ExceptionServices.ExceptionDispatchInfo.Throw()
   at ReportPortal.Shared.Internal.Delegating.ExponentialRetryRequestExecuter.<ExecuteAsync>d__14`1.MoveNext()
--- End of stack trace from previous location where exception was thrown ---
   at System.Runtime.ExceptionServices.ExceptionDispatchInfo.Throw()
   at System.Runtime.CompilerServices.TaskAwaiter.HandleNonSuccessAndDebuggerNotification(Task task)
   at ReportPortal.Shared.Reporter.LaunchReporter.<>c__DisplayClass25_0.<<Start>b__1>d.MoveNext()
--- End of stack trace from previous location where exception was thrown ---
   at System.Runtime.ExceptionServices.ExceptionDispatchInfo.Throw()
   at System.Runtime.CompilerServices.TaskAwaiter.HandleNonSuccessAndDebuggerNotification(Task task)
   at ReportPortal.Shared.Reporter.LaunchReporter.Sync()
   at ReportPortal.NUnitExtension.ReportPortalListener.FinishRun(String report) in C:\projects\agent-net-nunit\src\ReportPortal.NUnitExtension\ReportPortalListener.Launch.cs:line 113
   --- End of inner exception stack trace ---
   --- End of inner exception stack trace ---
   at ReportPortal.Shared.Reporter.TestReporter.<>c__DisplayClass24_0.<<Start>b__0>d.MoveNext()
   --- End of inner exception stack trace ---
   --- End of inner exception stack trace ---
   at ReportPortal.Shared.Reporter.TestReporter.<>c__DisplayClass24_0.<<Start>b__0>d.MoveNext()
   --- End of inner exception stack trace ---
   --- End of inner exception stack trace ---
   at ReportPortal.Shared.Reporter.TestReporter.<>c__DisplayClass24_0.<<Start>b__0>d.MoveNext()
   --- End of inner exception stack trace ---
   --- End of inner exception stack trace ---
   at ReportPortal.Shared.Reporter.TestReporter.<>c__DisplayClass24_0.<<Start>b__0>d.MoveNext()
   --- End of inner exception stack trace ---
   --- End of inner exception stack trace ---
TestReporter Error: 0 : 15:54:08.2663096 : 1-nunit3-console.exe : System.Exception: Cannot start test item due parent failed to start. ---> System.AggregateException: One or more errors occurred. ---> System.Exception: Cannot start test item due parent failed to start. ---> System.AggregateException: One or more errors occurred. ---> System.Exception: Cannot start test item due parent failed to start. ---> System.AggregateException: One or more errors occurred. ---> System.Exception: Cannot start test item due parent failed to start. ---> System.AggregateException: One or more errors occurred. ---> System.Exception: Cannot start test item due parent failed to start. ---> System.AggregateException: One or more errors occurred. ---> System.Exception: Cannot start test item due parent failed to start. ---> System.AggregateException: One or more errors occurred. ---> System.Net.Http.HttpRequestException: An error occurred while sending the request. ---> System.Net.WebException: Unable to connect to the remote server ---> System.Net.Sockets.SocketException: No connection could be made because the target machine actively refused it 127.0.0.1:80
   at System.Net.Sockets.Socket.InternalEndConnect(IAsyncResult asyncResult)
   at System.Net.Sockets.Socket.EndConnect(IAsyncResult asyncResult)
   at System.Net.ServicePoint.ConnectSocketInternal(Boolean connectFailure, Socket s4, Socket s6, Socket& socket, IPAddress& address, ConnectSocketState state, IAsyncResult asyncResult, Exception& exception)
   --- End of inner exception stack trace ---
   at System.Net.HttpWebRequest.EndGetRequestStream(IAsyncResult asyncResult, TransportContext& context)
   at System.Net.Http.HttpClientHandler.GetRequestStreamCallback(IAsyncResult ar)
   --- End of inner exception stack trace ---
   at System.Runtime.ExceptionServices.ExceptionDispatchInfo.Throw()
   at System.Runtime.CompilerServices.TaskAwaiter.HandleNonSuccessAndDebuggerNotification(Task task)
   at ReportPortal.Client.Resources.ServiceBaseResource.<SendHttpRequestAsync>d__12`1.MoveNext()
--- End of stack trace from previous location where exception was thrown ---
   at System.Runtime.ExceptionServices.ExceptionDispatchInfo.Throw()
   at System.Runtime.CompilerServices.TaskAwaiter.HandleNonSuccessAndDebuggerNotification(Task task)
   at ReportPortal.Shared.Internal.Delegating.BaseRequestExecuter.<ExecuteAsync>d__0`1.MoveNext()
--- End of stack trace from previous location where exception was thrown ---
   at System.Runtime.ExceptionServices.ExceptionDispatchInfo.Throw()
   at ReportPortal.Shared.Internal.Delegating.ExponentialRetryRequestExecuter.<ExecuteAsync>d__14`1.MoveNext()
--- End of stack trace from previous location where exception was thrown ---
   at System.Runtime.ExceptionServices.ExceptionDispatchInfo.Throw()
   at ReportPortal.Shared.Internal.Delegating.ExponentialRetryRequestExecuter.<ExecuteAsync>d__14`1.MoveNext()
--- End of stack trace from previous location where exception was thrown ---
   at System.Runtime.ExceptionServices.ExceptionDispatchInfo.Throw()
   at System.Runtime.CompilerServices.TaskAwaiter.HandleNonSuccessAndDebuggerNotification(Task task)
   at ReportPortal.Shared.Reporter.LaunchReporter.<>c__DisplayClass25_0.<<Start>b__1>d.MoveNext()
--- End of stack trace from previous location where exception was thrown ---
   at System.Runtime.ExceptionServices.ExceptionDispatchInfo.Throw()
   at System.Runtime.CompilerServices.TaskAwaiter.HandleNonSuccessAndDebuggerNotification(Task task)
   at ReportPortal.Shared.Reporter.LaunchReporter.Sync()
   at ReportPortal.NUnitExtension.ReportPortalListener.FinishRun(String report) in C:\projects\agent-net-nunit\src\ReportPortal.NUnitExtension\ReportPortalListener.Launch.cs:line 113
   --- End of inner exception stack trace ---
   --- End of inner exception stack trace ---
   at ReportPortal.Shared.Reporter.TestReporter.<>c__DisplayClass24_0.<<Start>b__0>d.MoveNext()
   --- End of inner exception stack trace ---
   --- End of inner exception stack trace ---
   at ReportPortal.Shared.Reporter.TestReporter.<>c__DisplayClass24_0.<<Start>b__0>d.MoveNext()
   --- End of inner exception stack trace ---
   --- End of inner exception stack trace ---
   at ReportPortal.Shared.Reporter.TestReporter.<>c__DisplayClass24_0.<<Start>b__0>d.MoveNext()
   --- End of inner exception stack trace ---
   --- End of inner exception stack trace ---
   at ReportPortal.Shared.Reporter.TestReporter.<>c__DisplayClass24_0.<<Start>b__0>d.MoveNext()
   --- End of inner exception stack trace ---
   --- End of inner exception stack trace ---
   at ReportPortal.Shared.Reporter.TestReporter.<>c__DisplayClass24_0.<<Start>b__0>d.MoveNext()
   --- End of inner exception stack trace ---
   --- End of inner exception stack trace ---
TestReporter Error: 0 : 